Workbook
Name Base: #REF!
Name Beg_Bal: #REF!
Name Clean_Data: #REF!,#REF!,#REF!,#REF!,#REF!,#REF!,#REF!,#REF!,#REF!,#REF!,#REF!,#REF!,#REF!,#REF!,#REF!,#REF!,#REF!,#REF!,#REF!
Name Comp1_DOX: #REF!
Name Comp1_name: #REF!
Name Comp1_WPX: #REF!
Name Comp1_zone: #REF!
Name Comp2_DOX: #REF!
Name Comp2_name: #REF!
Name Comp2_WPX: #REF!
Name Comp2_zone: #REF!
Name Comp3_DOX: #REF!
Name Comp3_name: #REF!
Name Comp3_WPX: #REF!
Name Comp3_zone: #REF!
Name Comp4_DOX: #REF!
Name Comp4_name: #REF!
Name Comp4_WPX: #REF!
Name Comp4_zone: #REF!
Name Comp5_DOX: #REF!
Name Comp5_name: #REF!
Name Comp5_WPX: #REF!
Name Comp5_zone: #REF!
Name competitors: #REF!
Name Consolidet_Sales_by_Customer: #REF!
Name countries: #REF!
Name Data: #REF!
Name DATA_ENG: #REF!
Name DATA_RUS: #REF!
Name DATA_RUS2: #REF!
Name Database1: #REF!
Name DHL: #REF!
Name DHL_DOX_new: #REF!
Name DHL_DOX_OLD: #REF!
Name DHL_vs_Competitors: #REF!
Name DHL_WPX_new: #REF!
Name DHL_WPX_OLD: #REF!
Name dhl_wpx_old_2: #REF!
Name discount: #REF!
Name discount_percentage: #REF!
Name EC_Countries: #REF!
Name ecxrates: '[2]DOX WB'!$C$31:$G$531
Name EDOX_ships: #REF!
Name EMS: #REF!
Name End_Bal: #REF!
Name Excel_BuiltIn__FilterDatabase: #REF!
Name Extra_Pay: #REF!
Name f: '[3]new tariff'!#REF!
Name figaro: #REF!
Name finaltdd12: '[4]DOM TDD12'!#REF!
Name finaltdd9: '[2]adjusted tdd9 rates'!$B$26:$F$527
Name Full_Print: #REF!
Name gh: Scheduled_Payment+Extra_Payment
Name HEADER_ENG: #REF!
Name Header_Row: ROW(#REF!)
Name HEADER_RUS: #REF!
Name HEADER_RUS2: #REF!
Name Int: #REF!
Name Interest_Rate: #REF!
Name khg: IF(Loan_Amount*Interest_Rate*Loan_Years*Loan_Start>0,1,0)

Sheet Лист опроса
A2: На основании данных, занесенных Вами в опросный лист, будет произведен расчет тарифов на наши услуги и сформировано коммерческое предложение.
A3: Общие параметры
A4: 1 | B4: Название компании | C4: 0 | V4: FIFO (first-in-first-out) первым вошел, первым идет на отправку.
A5: 2 | B5: Регион | C5: 0 | V5: FEFO (first-expired-first-out) — при работе по этому принципу первым отправляется товар, срок годности которого выходит раньше.
A6: 3 | B6: Тип товара | C6: 0 | V6: LIFO (last-in-first-out) первым на отправку идет товар, который поступил последним.
A7: 4 | B7: С какого срока требуется предоставление складских услуг? | C7: 0 | E7: Необходимо внести информацию, где текст выделен синим шрифтом | V7: LEFO (last­-ended-first-­out): это означает «последним заканчивается — первым выходит».
A8: 5 | B8: Предполагаемый срок действия договора? | C8: 0 | V8: FPFO (first-product-first-out): «первый произведен — первый выходит».
A9: 6 | B9: Кол-во наименований продукции (артикулов), которое будет обрабатываться на складе | C9: 0 | V9: BBD (Best Before Day) указывает на приоритет в отгрузке — «рекомендуемый срок хранения» (Best Before Day не равно сроку годности товара (UBD, англ. Use By Date).
A10: 7 | B10: Кол-во артикулов на складе, обрабатываемых за расчетный период среднее в месяц | C10: 0
A11: 8 | B11: Максимальный и средний вес короба, кг | C11: 0 | D11: 0
A12: 9 | B12: Особые условия хранения | C12: 0
A13: 10 | B13: Укажите пожалуйста требуемый тип передачи данных (1-й, 2-й или 3-й - см. примечание) и наличие ЭДО | C13: 0
A14: 11 | B14: Наличие ЭДО | C14: 0 | E14: GUID
A15: 12 | B15: Ваша система учёта с которой будет настроена интеграция | C15: 0
A16: 13 | B16: Требуемый график работы склада | C16: 0
A17: Вход товара на склад
A18: 1 | B18: Информация по приходящему а/т и объему
A19: В месяц | B19: Тип а/т | C19: Кол-во а/м | E19: Среднее кол-во в 1 а/м: | H19: Размещение паллет в 2-яруса, да/нет
E20: монопаллета (1 артикул) | F20: "и" смешанных паллет | G20: "и" коробов в навал
C21: среднее | D21: макс. | E21: среднее | F21: среднее | G21: среднее
B22: ж/д контейнер 40 фут | C22: 0 | D22: 0 | E22: 0 | F22: 0 | G22: 0 | H22: 0
B23: ж/д контейнер 20 фут | C23: 0 | D23: 0 | E23: 0 | F23: 0 | G23: 0 | H23: 0
B24: до 20 т (Еврофура) | C24: 0 | D24: 0 | E24: 0 | F24: 0 | G24: 0 | H24: 0
B25: до 10 т (Маз/Камаз) | C25: 0 | D25: 0 | E25: 0 | F25: 0 | G25: 0 | H25: 0
B26: до 5 т (Зил/Газ) | C26: 0 | D26: 0 | E26: 0 | F26: 0 | G26: 0 | H26: 0
B27: до 3,5 т (Бычок) | C27: 0 | D27: 0 | E27: 0 | F27: 0 | G27: 0 | H27: 0
B28: до 1,5 т (Газель) | C28: 0 | D28: 0 | E28: 0 | F28: 0 | G28: 0 | H28: 0
B29: Всего: | C29: =SUM(C22:C28) -> 0 | D29: =SUM(D22:D28) -> 0 | E29: =SUMPRODUCT(E22:E28,$C22:$C28)/$C29 -> #DIV/0! | F29: =SUMPRODUCT(F22:F28,$C22:$C28)/$C29 -> #DIV/0! | G29: =SUMPRODUCT(G22:G28,$C22:$C28)/$C29 -> #DIV/0!
A30: 2 | B30: Тип используемой тары (поддона) , для товаров не входящих в навал | C30: EURO (120 х 80) | D30: US (120 х 120) | E30: FIN (120 х 100) | F30: Прочие (в т.ч. транспортные паллеты, негабарит, слипшиты и т.п.), указать размеры
B31: % от общего объема | C31: 0 | D31: 0 | E31: 0 | F31: 0
A32: 3 | B32: Изменение объемов обработки в течение года | C32: январь | D32: февраль | E32: март | F32: апрель | G32: май | H32: июнь | I32: июль | J32: август | K32: сентябрь | L32: октябрь | M32: ноябрь | N32: декабрь
B33: % от среднего значения (данных в анкете) | C33: 1 | D33: 1 | E33: 1 | F33: 1 | G33: 1 | H33: 1 | I33: 1 | J33: 1 | K33: 1 | L33: 1 | M33: 1 | N33: 1
A34: 4 | B34: Изменение объемов обработки в течение месяца | C34: 1 неделя | D34: 2 неделя | E34: 3 неделя | F34: 4 неделя | G34: 5 неделя
B35: % от среднего значения (данных в анкете) | C35: 0 | D35: 0 | E35: 0 | F35: 0 | G35: 0
A36: 5 | B36: Кол-во артикулов в одной машине | C36: среднее | D36: максим.
C37: 0 | D37: 0
A38: 6 | B38: Кол-во артикулов на одной смешанной паллете | C38: среднее | D38: максим.
C39: 0 | D39: 0
A40: 7 | B40: Вес одной паллеты с грузом кг | C40: среднее | D40: максим.
C41: 0 | D41: 0
...

Sheet Лист2 (2)
B2: Услуга | C2: описание услуги | D2: единица измерения
B4: Выгрузка паллеты | C4: Разгрузка паллет с использованием специальных технических средств. | D4: паллетоместо
B5: Приемка монопаллеты | C5: Приемка в систему учета по номенклатуре и количеству. На одной паллете один артикул. | D5: паллетоместо
B6: Приемка смешанной паллеты | C6: Приемка коробов поступивших на паллете. На одной паллете более одного артикула. Включает снятие транспортировочного стретча, сортировку по наименованиям, приемку в систему учета по номенклатуре и количеству. | D6: упаковка/коробка
B7: Выгрузка коробов в навал | C7: Ручная выгрузка коробов (ТМЦ пришли без паллет) обмотка стретч пленкой и предоставление паллет для хранения оплачивается дополнительно, включает сортировку по наименованию | D7: упаковка/коробка
B8: Приемка коробов валом | C8: Приемка в систему учета (ТМЦ пришли без паллет и не требуют машинной обработки). | D8: упаковка/коробка
B9: Штучная приемка ТМЦ | C9: Поштучная приёмка по штрихкоду со штуки. | D9: штука
B10: ПРР механизированный, выгрузка негабаритных ТМЦ | C10: Разгрузка с использованием специальных технических средств. На одном месте один артикул. | D10: шт/м3
B11: Приемка негабаритных ТМЦ | C11: Приемка в систему учета по номенклатуре и количеству, размещение в зону хранения. На одном месте один артикул. | D11: шт/м3
B12: Подбор штук | C12: Поштучный подбор ТМЦ. Поиск в зоне хранения и подготовка к отгрузке по учетной системе без доп.упаковки. | D12: штука
B13: Подбор короба | C13: Подбор ТМЦ - упаковка/коробка/мешок/ведро. Поиск в зоне хранения и подготовка к отгрузке по учетной системе. | D13: упаковка/коробка
B14: Подбор монопаллеты | C14: Подбор ТМЦ - монопаллета Поиск в зоне хранения и подготовка к отгрузке по учетной системе. | D14: паллетоместо
... B19: ПРР механизированный, отгрузка негабаритных ТМЦ | C19: Погрузка транспортных средств с использованием специальных технических средств. | D19: шт/м3

Sheet Лист2
A1: Предоставление стандартного деревянного поддона Eur 120*80 для хранения
A2: Предоставление стандартного деревянного поддона Eur 120*80 для отгрузки товара
A3: Дополнительное вложение в короб
A4: co-packing (копакинг) - услуги по упаковке, переупаковке, нанесению стикеров и маркировке товаров
A5: Расформирование заказа
A6: Пломбирование автомобиля (пластиковая пломба)
A7: Аренда офиса
A8: Кросс-докинг
